[2024-05-26 10:46:28,912] [INFO] db - Connected to mongo.
[2024-05-26 10:46:40,749] [INFO] app - in root
[2024-05-26 10:48:37,352] [INFO] db - Mongo connection closed.
[2024-05-27 18:44:06,346] [ERROR] app - Request invalid. [{'type': 'missing', 'loc': ('body', 'address', 'id'), 'msg': 'Field required', 'input': {'addr': 'ddd', 'state': 'qld', 'zipcode': '2000', 'country': 'aus'}, 'url': 'https://errors.pydantic.dev/2.5/v/missing'}]
[2024-05-27 18:48:42,450] [ERROR] app - Request invalid. [{'type': 'missing', 'loc': ('body', 'address', 'id'), 'msg': 'Field required', 'input': {'addr': 'ddd', 'state': 'qld', 'zipcode': '2000', 'country': 'aus'}, 'url': 'https://errors.pydantic.dev/2.5/v/missing'}]
[2024-05-27 18:48:48,094] [ERROR] app - Request invalid. [{'type': 'missing', 'loc': ('body', 'address', 'id'), 'msg': 'Field required', 'input': {'addr': 'ddd', 'state': 'qld', 'zipcode': '2000', 'country': 'aus'}, 'url': 'https://errors.pydantic.dev/2.5/v/missing'}]
[2024-05-27 18:54:04,821] [ERROR] app - Request invalid. [{'type': 'missing', 'loc': ('body', 'address', 'id'), 'msg': 'Field required', 'input': {'addr': 'ddd', 'state': 'qld', 'zipcode': '2000', 'country': 'aus'}, 'url': 'https://errors.pydantic.dev/2.5/v/missing'}]
[2024-05-27 18:57:19,657] [ERROR] app - Request invalid. [{'type': 'missing', 'loc': ('body', 'address', 'id'), 'msg': 'Field required', 'input': {'addr': 'ddd', 'state': 'qld', 'zipcode': '2000', 'country': 'aus'}, 'url': 'https://errors.pydantic.dev/2.5/v/missing'}]
[2024-05-27 19:58:20,424] [ERROR] app - Request invalid. [{'type': 'value_error', 'loc': ('body', 'address', 'user_object_id'), 'msg': 'Value error, Invalid ObjectId', 'input': 'string', 'ctx': {'error': ValueError('Invalid ObjectId')}, 'url': 'https://errors.pydantic.dev/2.5/v/value_error'}]
[2024-06-26 09:12:04,880] [ERROR] base_events - Future exception was never retrieved
future: <Future finished exception=InvalidDocument("cannot encode object: {'name'}, of type: <class 'set'>")>
Traceback (most recent call last):
  File "/home/revit/python-projects/ecommerce-app/backend/venv/lib/python3.9/site-packages/motor/core.py", line 1683, in _to_list
    result = get_more_result.result()
  File "/home/revit/python-projects/ecommerce-app/backend/venv/lib/python3.9/site-packages/motor/core.py", line 1908, in _on_started
    pymongo_cursor = future.result()
  File "/usr/lib/python3.9/concurrent/futures/thread.py", line 52, in run
    result = self.fn(*self.args, **self.kwargs)
  File "/home/revit/python-projects/ecommerce-app/backend/venv/lib/python3.9/site-packages/pymongo/collection.py", line 2720, in aggregate
    return self._aggregate(
  File "/home/revit/python-projects/ecommerce-app/backend/venv/lib/python3.9/site-packages/pymongo/_csot.py", line 107, in csot_wrapper
    return func(self, *args, **kwargs)
  File "/home/revit/python-projects/ecommerce-app/backend/venv/lib/python3.9/site-packages/pymongo/collection.py", line 2627, in _aggregate
    return self.__database.client._retryable_read(
  File "/home/revit/python-projects/ecommerce-app/backend/venv/lib/python3.9/site-packages/pymongo/mongo_client.py", line 1492, in _retryable_read
    return self._retry_internal(
  File "/home/revit/python-projects/ecommerce-app/backend/venv/lib/python3.9/site-packages/pymongo/_csot.py", line 107, in csot_wrapper
    return func(self, *args, **kwargs)
  File "/home/revit/python-projects/ecommerce-app/backend/venv/lib/python3.9/site-packages/pymongo/mongo_client.py", line 1453, in _retry_internal
    return _ClientConnectionRetryable(
  File "/home/revit/python-projects/ecommerce-app/backend/venv/lib/python3.9/site-packages/pymongo/mongo_client.py", line 2315, in run
    return self._read() if self._is_read else self._write()
  File "/home/revit/python-projects/ecommerce-app/backend/venv/lib/python3.9/site-packages/pymongo/mongo_client.py", line 2445, in _read
    return self._func(self._session, self._server, conn, read_pref)  # type: ignore
  File "/home/revit/python-projects/ecommerce-app/backend/venv/lib/python3.9/site-packages/pymongo/aggregation.py", line 164, in get_cursor
    result = conn.command(
  File "/home/revit/python-projects/ecommerce-app/backend/venv/lib/python3.9/site-packages/pymongo/helpers.py", line 322, in inner
    return func(*args, **kwargs)
  File "/home/revit/python-projects/ecommerce-app/backend/venv/lib/python3.9/site-packages/pymongo/pool.py", line 996, in command
    self._raise_connection_failure(error)
  File "/home/revit/python-projects/ecommerce-app/backend/venv/lib/python3.9/site-packages/pymongo/pool.py", line 968, in command
    return command(
  File "/home/revit/python-projects/ecommerce-app/backend/venv/lib/python3.9/site-packages/pymongo/network.py", line 151, in command
    request_id, msg, size, max_doc_size = message._op_msg(
  File "/home/revit/python-projects/ecommerce-app/backend/venv/lib/python3.9/site-packages/pymongo/message.py", line 762, in _op_msg
    return _op_msg_uncompressed(flags, command, identifier, docs, opts)
bson.errors.InvalidDocument: cannot encode object: {'name'}, of type: <class 'set'>
[2024-06-26 09:15:11,840] [ERROR] base_events - Future exception was never retrieved
future: <Future finished exception=InvalidDocument("cannot encode object: {'name'}, of type: <class 'set'>")>
Traceback (most recent call last):
  File "/home/revit/python-projects/ecommerce-app/backend/venv/lib/python3.9/site-packages/motor/core.py", line 1683, in _to_list
    result = get_more_result.result()
  File "/home/revit/python-projects/ecommerce-app/backend/venv/lib/python3.9/site-packages/motor/core.py", line 1908, in _on_started
    pymongo_cursor = future.result()
  File "/usr/lib/python3.9/concurrent/futures/thread.py", line 52, in run
    result = self.fn(*self.args, **self.kwargs)
  File "/home/revit/python-projects/ecommerce-app/backend/venv/lib/python3.9/site-packages/pymongo/collection.py", line 2720, in aggregate
    return self._aggregate(
  File "/home/revit/python-projects/ecommerce-app/backend/venv/lib/python3.9/site-packages/pymongo/_csot.py", line 107, in csot_wrapper
    return func(self, *args, **kwargs)
  File "/home/revit/python-projects/ecommerce-app/backend/venv/lib/python3.9/site-packages/pymongo/collection.py", line 2627, in _aggregate
    return self.__database.client._retryable_read(
  File "/home/revit/python-projects/ecommerce-app/backend/venv/lib/python3.9/site-packages/pymongo/mongo_client.py", line 1492, in _retryable_read
    return self._retry_internal(
  File "/home/revit/python-projects/ecommerce-app/backend/venv/lib/python3.9/site-packages/pymongo/_csot.py", line 107, in csot_wrapper
    return func(self, *args, **kwargs)
  File "/home/revit/python-projects/ecommerce-app/backend/venv/lib/python3.9/site-packages/pymongo/mongo_client.py", line 1453, in _retry_internal
    return _ClientConnectionRetryable(
  File "/home/revit/python-projects/ecommerce-app/backend/venv/lib/python3.9/site-packages/pymongo/mongo_client.py", line 2315, in run
    return self._read() if self._is_read else self._write()
  File "/home/revit/python-projects/ecommerce-app/backend/venv/lib/python3.9/site-packages/pymongo/mongo_client.py", line 2445, in _read
    return self._func(self._session, self._server, conn, read_pref)  # type: ignore
  File "/home/revit/python-projects/ecommerce-app/backend/venv/lib/python3.9/site-packages/pymongo/aggregation.py", line 164, in get_cursor
    result = conn.command(
  File "/home/revit/python-projects/ecommerce-app/backend/venv/lib/python3.9/site-packages/pymongo/helpers.py", line 322, in inner
    return func(*args, **kwargs)
  File "/home/revit/python-projects/ecommerce-app/backend/venv/lib/python3.9/site-packages/pymongo/pool.py", line 996, in command
    self._raise_connection_failure(error)
  File "/home/revit/python-projects/ecommerce-app/backend/venv/lib/python3.9/site-packages/pymongo/pool.py", line 968, in command
    return command(
  File "/home/revit/python-projects/ecommerce-app/backend/venv/lib/python3.9/site-packages/pymongo/network.py", line 151, in command
    request_id, msg, size, max_doc_size = message._op_msg(
  File "/home/revit/python-projects/ecommerce-app/backend/venv/lib/python3.9/site-packages/pymongo/message.py", line 762, in _op_msg
    return _op_msg_uncompressed(flags, command, identifier, docs, opts)
bson.errors.InvalidDocument: cannot encode object: {'name'}, of type: <class 'set'>
[2024-06-26 09:16:44,378] [ERROR] base_events - Future exception was never retrieved
future: <Future finished exception=InvalidDocument("cannot encode object: {'name'}, of type: <class 'set'>")>
Traceback (most recent call last):
  File "/home/revit/python-projects/ecommerce-app/backend/venv/lib/python3.9/site-packages/motor/core.py", line 1683, in _to_list
    result = get_more_result.result()
  File "/home/revit/python-projects/ecommerce-app/backend/venv/lib/python3.9/site-packages/motor/core.py", line 1908, in _on_started
    pymongo_cursor = future.result()
  File "/usr/lib/python3.9/concurrent/futures/thread.py", line 52, in run
    result = self.fn(*self.args, **self.kwargs)
  File "/home/revit/python-projects/ecommerce-app/backend/venv/lib/python3.9/site-packages/pymongo/collection.py", line 2720, in aggregate
    return self._aggregate(
  File "/home/revit/python-projects/ecommerce-app/backend/venv/lib/python3.9/site-packages/pymongo/_csot.py", line 107, in csot_wrapper
    return func(self, *args, **kwargs)
  File "/home/revit/python-projects/ecommerce-app/backend/venv/lib/python3.9/site-packages/pymongo/collection.py", line 2627, in _aggregate
    return self.__database.client._retryable_read(
  File "/home/revit/python-projects/ecommerce-app/backend/venv/lib/python3.9/site-packages/pymongo/mongo_client.py", line 1492, in _retryable_read
    return self._retry_internal(
  File "/home/revit/python-projects/ecommerce-app/backend/venv/lib/python3.9/site-packages/pymongo/_csot.py", line 107, in csot_wrapper
    return func(self, *args, **kwargs)
  File "/home/revit/python-projects/ecommerce-app/backend/venv/lib/python3.9/site-packages/pymongo/mongo_client.py", line 1453, in _retry_internal
    return _ClientConnectionRetryable(
  File "/home/revit/python-projects/ecommerce-app/backend/venv/lib/python3.9/site-packages/pymongo/mongo_client.py", line 2315, in run
    return self._read() if self._is_read else self._write()
  File "/home/revit/python-projects/ecommerce-app/backend/venv/lib/python3.9/site-packages/pymongo/mongo_client.py", line 2445, in _read
    return self._func(self._session, self._server, conn, read_pref)  # type: ignore
  File "/home/revit/python-projects/ecommerce-app/backend/venv/lib/python3.9/site-packages/pymongo/aggregation.py", line 164, in get_cursor
    result = conn.command(
  File "/home/revit/python-projects/ecommerce-app/backend/venv/lib/python3.9/site-packages/pymongo/helpers.py", line 322, in inner
    return func(*args, **kwargs)
  File "/home/revit/python-projects/ecommerce-app/backend/venv/lib/python3.9/site-packages/pymongo/pool.py", line 996, in command
    self._raise_connection_failure(error)
  File "/home/revit/python-projects/ecommerce-app/backend/venv/lib/python3.9/site-packages/pymongo/pool.py", line 968, in command
    return command(
  File "/home/revit/python-projects/ecommerce-app/backend/venv/lib/python3.9/site-packages/pymongo/network.py", line 151, in command
    request_id, msg, size, max_doc_size = message._op_msg(
  File "/home/revit/python-projects/ecommerce-app/backend/venv/lib/python3.9/site-packages/pymongo/message.py", line 762, in _op_msg
    return _op_msg_uncompressed(flags, command, identifier, docs, opts)
bson.errors.InvalidDocument: cannot encode object: {'name'}, of type: <class 'set'>
[2024-06-26 09:16:44,418] [ERROR] base_events - Future exception was never retrieved
future: <Future finished exception=InvalidDocument("cannot encode object: {'name'}, of type: <class 'set'>")>
Traceback (most recent call last):
  File "/home/revit/python-projects/ecommerce-app/backend/venv/lib/python3.9/site-packages/motor/core.py", line 1683, in _to_list
    result = get_more_result.result()
  File "/home/revit/python-projects/ecommerce-app/backend/venv/lib/python3.9/site-packages/motor/core.py", line 1908, in _on_started
    pymongo_cursor = future.result()
  File "/usr/lib/python3.9/concurrent/futures/thread.py", line 52, in run
    result = self.fn(*self.args, **self.kwargs)
  File "/home/revit/python-projects/ecommerce-app/backend/venv/lib/python3.9/site-packages/pymongo/collection.py", line 2720, in aggregate
    return self._aggregate(
  File "/home/revit/python-projects/ecommerce-app/backend/venv/lib/python3.9/site-packages/pymongo/_csot.py", line 107, in csot_wrapper
    return func(self, *args, **kwargs)
  File "/home/revit/python-projects/ecommerce-app/backend/venv/lib/python3.9/site-packages/pymongo/collection.py", line 2627, in _aggregate
    return self.__database.client._retryable_read(
  File "/home/revit/python-projects/ecommerce-app/backend/venv/lib/python3.9/site-packages/pymongo/mongo_client.py", line 1492, in _retryable_read
    return self._retry_internal(
  File "/home/revit/python-projects/ecommerce-app/backend/venv/lib/python3.9/site-packages/pymongo/_csot.py", line 107, in csot_wrapper
    return func(self, *args, **kwargs)
  File "/home/revit/python-projects/ecommerce-app/backend/venv/lib/python3.9/site-packages/pymongo/mongo_client.py", line 1453, in _retry_internal
    return _ClientConnectionRetryable(
  File "/home/revit/python-projects/ecommerce-app/backend/venv/lib/python3.9/site-packages/pymongo/mongo_client.py", line 2315, in run
    return self._read() if self._is_read else self._write()
  File "/home/revit/python-projects/ecommerce-app/backend/venv/lib/python3.9/site-packages/pymongo/mongo_client.py", line 2445, in _read
    return self._func(self._session, self._server, conn, read_pref)  # type: ignore
  File "/home/revit/python-projects/ecommerce-app/backend/venv/lib/python3.9/site-packages/pymongo/aggregation.py", line 164, in get_cursor
    result = conn.command(
  File "/home/revit/python-projects/ecommerce-app/backend/venv/lib/python3.9/site-packages/pymongo/helpers.py", line 322, in inner
    return func(*args, **kwargs)
  File "/home/revit/python-projects/ecommerce-app/backend/venv/lib/python3.9/site-packages/pymongo/pool.py", line 996, in command
    self._raise_connection_failure(error)
  File "/home/revit/python-projects/ecommerce-app/backend/venv/lib/python3.9/site-packages/pymongo/pool.py", line 968, in command
    return command(
  File "/home/revit/python-projects/ecommerce-app/backend/venv/lib/python3.9/site-packages/pymongo/network.py", line 151, in command
    request_id, msg, size, max_doc_size = message._op_msg(
  File "/home/revit/python-projects/ecommerce-app/backend/venv/lib/python3.9/site-packages/pymongo/message.py", line 762, in _op_msg
    return _op_msg_uncompressed(flags, command, identifier, docs, opts)
bson.errors.InvalidDocument: cannot encode object: {'name'}, of type: <class 'set'>
[2024-06-26 09:19:04,594] [ERROR] base_events - Future exception was never retrieved
future: <Future finished exception=InvalidDocument("cannot encode object: {'name'}, of type: <class 'set'>")>
Traceback (most recent call last):
  File "/home/revit/python-projects/ecommerce-app/backend/venv/lib/python3.9/site-packages/motor/core.py", line 1683, in _to_list
    result = get_more_result.result()
  File "/home/revit/python-projects/ecommerce-app/backend/venv/lib/python3.9/site-packages/motor/core.py", line 1908, in _on_started
    pymongo_cursor = future.result()
  File "/usr/lib/python3.9/concurrent/futures/thread.py", line 52, in run
    result = self.fn(*self.args, **self.kwargs)
  File "/home/revit/python-projects/ecommerce-app/backend/venv/lib/python3.9/site-packages/pymongo/collection.py", line 2720, in aggregate
    return self._aggregate(
  File "/home/revit/python-projects/ecommerce-app/backend/venv/lib/python3.9/site-packages/pymongo/_csot.py", line 107, in csot_wrapper
    return func(self, *args, **kwargs)
  File "/home/revit/python-projects/ecommerce-app/backend/venv/lib/python3.9/site-packages/pymongo/collection.py", line 2627, in _aggregate
    return self.__database.client._retryable_read(
  File "/home/revit/python-projects/ecommerce-app/backend/venv/lib/python3.9/site-packages/pymongo/mongo_client.py", line 1492, in _retryable_read
    return self._retry_internal(
  File "/home/revit/python-projects/ecommerce-app/backend/venv/lib/python3.9/site-packages/pymongo/_csot.py", line 107, in csot_wrapper
    return func(self, *args, **kwargs)
  File "/home/revit/python-projects/ecommerce-app/backend/venv/lib/python3.9/site-packages/pymongo/mongo_client.py", line 1453, in _retry_internal
    return _ClientConnectionRetryable(
  File "/home/revit/python-projects/ecommerce-app/backend/venv/lib/python3.9/site-packages/pymongo/mongo_client.py", line 2315, in run
    return self._read() if self._is_read else self._write()
  File "/home/revit/python-projects/ecommerce-app/backend/venv/lib/python3.9/site-packages/pymongo/mongo_client.py", line 2445, in _read
    return self._func(self._session, self._server, conn, read_pref)  # type: ignore
  File "/home/revit/python-projects/ecommerce-app/backend/venv/lib/python3.9/site-packages/pymongo/aggregation.py", line 164, in get_cursor
    result = conn.command(
  File "/home/revit/python-projects/ecommerce-app/backend/venv/lib/python3.9/site-packages/pymongo/helpers.py", line 322, in inner
    return func(*args, **kwargs)
  File "/home/revit/python-projects/ecommerce-app/backend/venv/lib/python3.9/site-packages/pymongo/pool.py", line 996, in command
    self._raise_connection_failure(error)
  File "/home/revit/python-projects/ecommerce-app/backend/venv/lib/python3.9/site-packages/pymongo/pool.py", line 968, in command
    return command(
  File "/home/revit/python-projects/ecommerce-app/backend/venv/lib/python3.9/site-packages/pymongo/network.py", line 151, in command
    request_id, msg, size, max_doc_size = message._op_msg(
  File "/home/revit/python-projects/ecommerce-app/backend/venv/lib/python3.9/site-packages/pymongo/message.py", line 762, in _op_msg
    return _op_msg_uncompressed(flags, command, identifier, docs, opts)
bson.errors.InvalidDocument: cannot encode object: {'name'}, of type: <class 'set'>
[2024-06-26 09:24:09,990] [ERROR] base_events - Future exception was never retrieved
future: <Future finished exception=InvalidDocument("cannot encode object: {'name'}, of type: <class 'set'>")>
Traceback (most recent call last):
  File "/home/revit/python-projects/ecommerce-app/backend/venv/lib/python3.9/site-packages/motor/core.py", line 1683, in _to_list
    result = get_more_result.result()
  File "/home/revit/python-projects/ecommerce-app/backend/venv/lib/python3.9/site-packages/motor/core.py", line 1908, in _on_started
    pymongo_cursor = future.result()
  File "/usr/lib/python3.9/concurrent/futures/thread.py", line 52, in run
    result = self.fn(*self.args, **self.kwargs)
  File "/home/revit/python-projects/ecommerce-app/backend/venv/lib/python3.9/site-packages/pymongo/collection.py", line 2720, in aggregate
    return self._aggregate(
  File "/home/revit/python-projects/ecommerce-app/backend/venv/lib/python3.9/site-packages/pymongo/_csot.py", line 107, in csot_wrapper
    return func(self, *args, **kwargs)
  File "/home/revit/python-projects/ecommerce-app/backend/venv/lib/python3.9/site-packages/pymongo/collection.py", line 2627, in _aggregate
    return self.__database.client._retryable_read(
  File "/home/revit/python-projects/ecommerce-app/backend/venv/lib/python3.9/site-packages/pymongo/mongo_client.py", line 1492, in _retryable_read
    return self._retry_internal(
  File "/home/revit/python-projects/ecommerce-app/backend/venv/lib/python3.9/site-packages/pymongo/_csot.py", line 107, in csot_wrapper
    return func(self, *args, **kwargs)
  File "/home/revit/python-projects/ecommerce-app/backend/venv/lib/python3.9/site-packages/pymongo/mongo_client.py", line 1453, in _retry_internal
    return _ClientConnectionRetryable(
  File "/home/revit/python-projects/ecommerce-app/backend/venv/lib/python3.9/site-packages/pymongo/mongo_client.py", line 2315, in run
    return self._read() if self._is_read else self._write()
  File "/home/revit/python-projects/ecommerce-app/backend/venv/lib/python3.9/site-packages/pymongo/mongo_client.py", line 2445, in _read
    return self._func(self._session, self._server, conn, read_pref)  # type: ignore
  File "/home/revit/python-projects/ecommerce-app/backend/venv/lib/python3.9/site-packages/pymongo/aggregation.py", line 164, in get_cursor
    result = conn.command(
  File "/home/revit/python-projects/ecommerce-app/backend/venv/lib/python3.9/site-packages/pymongo/helpers.py", line 322, in inner
    return func(*args, **kwargs)
  File "/home/revit/python-projects/ecommerce-app/backend/venv/lib/python3.9/site-packages/pymongo/pool.py", line 996, in command
    self._raise_connection_failure(error)
  File "/home/revit/python-projects/ecommerce-app/backend/venv/lib/python3.9/site-packages/pymongo/pool.py", line 968, in command
    return command(
  File "/home/revit/python-projects/ecommerce-app/backend/venv/lib/python3.9/site-packages/pymongo/network.py", line 151, in command
    request_id, msg, size, max_doc_size = message._op_msg(
  File "/home/revit/python-projects/ecommerce-app/backend/venv/lib/python3.9/site-packages/pymongo/message.py", line 762, in _op_msg
    return _op_msg_uncompressed(flags, command, identifier, docs, opts)
bson.errors.InvalidDocument: cannot encode object: {'name'}, of type: <class 'set'>
[2024-06-26 09:25:28,169] [ERROR] base_events - Future exception was never retrieved
future: <Future finished exception=InvalidDocument("cannot encode object: {'name'}, of type: <class 'set'>")>
Traceback (most recent call last):
  File "/home/revit/python-projects/ecommerce-app/backend/venv/lib/python3.9/site-packages/motor/core.py", line 1683, in _to_list
    result = get_more_result.result()
  File "/home/revit/python-projects/ecommerce-app/backend/venv/lib/python3.9/site-packages/motor/core.py", line 1908, in _on_started
    pymongo_cursor = future.result()
  File "/usr/lib/python3.9/concurrent/futures/thread.py", line 52, in run
    result = self.fn(*self.args, **self.kwargs)
  File "/home/revit/python-projects/ecommerce-app/backend/venv/lib/python3.9/site-packages/pymongo/collection.py", line 2720, in aggregate
    return self._aggregate(
  File "/home/revit/python-projects/ecommerce-app/backend/venv/lib/python3.9/site-packages/pymongo/_csot.py", line 107, in csot_wrapper
    return func(self, *args, **kwargs)
  File "/home/revit/python-projects/ecommerce-app/backend/venv/lib/python3.9/site-packages/pymongo/collection.py", line 2627, in _aggregate
    return self.__database.client._retryable_read(
  File "/home/revit/python-projects/ecommerce-app/backend/venv/lib/python3.9/site-packages/pymongo/mongo_client.py", line 1492, in _retryable_read
    return self._retry_internal(
  File "/home/revit/python-projects/ecommerce-app/backend/venv/lib/python3.9/site-packages/pymongo/_csot.py", line 107, in csot_wrapper
    return func(self, *args, **kwargs)
  File "/home/revit/python-projects/ecommerce-app/backend/venv/lib/python3.9/site-packages/pymongo/mongo_client.py", line 1453, in _retry_internal
    return _ClientConnectionRetryable(
  File "/home/revit/python-projects/ecommerce-app/backend/venv/lib/python3.9/site-packages/pymongo/mongo_client.py", line 2315, in run
    return self._read() if self._is_read else self._write()
  File "/home/revit/python-projects/ecommerce-app/backend/venv/lib/python3.9/site-packages/pymongo/mongo_client.py", line 2445, in _read
    return self._func(self._session, self._server, conn, read_pref)  # type: ignore
  File "/home/revit/python-projects/ecommerce-app/backend/venv/lib/python3.9/site-packages/pymongo/aggregation.py", line 164, in get_cursor
    result = conn.command(
  File "/home/revit/python-projects/ecommerce-app/backend/venv/lib/python3.9/site-packages/pymongo/helpers.py", line 322, in inner
    return func(*args, **kwargs)
  File "/home/revit/python-projects/ecommerce-app/backend/venv/lib/python3.9/site-packages/pymongo/pool.py", line 996, in command
    self._raise_connection_failure(error)
  File "/home/revit/python-projects/ecommerce-app/backend/venv/lib/python3.9/site-packages/pymongo/pool.py", line 968, in command
    return command(
  File "/home/revit/python-projects/ecommerce-app/backend/venv/lib/python3.9/site-packages/pymongo/network.py", line 151, in command
    request_id, msg, size, max_doc_size = message._op_msg(
  File "/home/revit/python-projects/ecommerce-app/backend/venv/lib/python3.9/site-packages/pymongo/message.py", line 762, in _op_msg
    return _op_msg_uncompressed(flags, command, identifier, docs, opts)
bson.errors.InvalidDocument: cannot encode object: {'name'}, of type: <class 'set'>
[2024-06-27 15:39:32,345] [ERROR] app - Request invalid. [{'type': 'missing', 'loc': ('query', 'category'), 'msg': 'Field required', 'input': None, 'url': 'https://errors.pydantic.dev/2.5/v/missing'}]
[2024-06-27 17:54:02,957] [ERROR] app - Request invalid. [{'type': 'missing', 'loc': ('query', 'per_page'), 'msg': 'Field required', 'input': None, 'url': 'https://errors.pydantic.dev/2.5/v/missing'}, {'type': 'missing', 'loc': ('query', 'page'), 'msg': 'Field required', 'input': None, 'url': 'https://errors.pydantic.dev/2.5/v/missing'}]
[2024-06-27 17:54:30,642] [ERROR] app - Request invalid. [{'type': 'missing', 'loc': ('query', 'per_page'), 'msg': 'Field required', 'input': None, 'url': 'https://errors.pydantic.dev/2.5/v/missing'}]
[2024-06-28 10:45:11,242] [ERROR] app - Request invalid. [{'type': 'missing', 'loc': ('query', 'page_size'), 'msg': 'Field required', 'input': None, 'url': 'https://errors.pydantic.dev/2.5/v/missing'}, {'type': 'missing', 'loc': ('query', 'page_no'), 'msg': 'Field required', 'input': None, 'url': 'https://errors.pydantic.dev/2.5/v/missing'}]
[2024-06-28 18:28:47,295] [ERROR] app - Request invalid. [{'type': 'int_parsing', 'loc': ('query', 'page_size'), 'msg': 'Input should be a valid integer, unable to parse string as an integer', 'input': 'undefined', 'url': 'https://errors.pydantic.dev/2.5/v/int_parsing'}]
[2024-06-28 18:28:47,455] [ERROR] app - Request invalid. [{'type': 'int_parsing', 'loc': ('query', 'page_size'), 'msg': 'Input should be a valid integer, unable to parse string as an integer', 'input': 'undefined', 'url': 'https://errors.pydantic.dev/2.5/v/int_parsing'}]
[2024-06-28 18:29:19,615] [ERROR] app - Request invalid. [{'type': 'int_parsing', 'loc': ('query', 'page_size'), 'msg': 'Input should be a valid integer, unable to parse string as an integer', 'input': 'undefined', 'url': 'https://errors.pydantic.dev/2.5/v/int_parsing'}]
[2024-06-28 18:29:19,682] [ERROR] app - Request invalid. [{'type': 'int_parsing', 'loc': ('query', 'page_size'), 'msg': 'Input should be a valid integer, unable to parse string as an integer', 'input': 'undefined', 'url': 'https://errors.pydantic.dev/2.5/v/int_parsing'}]
[2024-06-30 18:13:38,036] [ERROR] app - Request invalid. [{'type': 'int_parsing', 'loc': ('query', 'page_no'), 'msg': 'Input should be a valid integer, unable to parse string as an integer', 'input': '3\\4', 'url': 'https://errors.pydantic.dev/2.5/v/int_parsing'}]
[2024-07-23 08:06:41,128] [ERROR] app - Request invalid. [{'type': 'int_parsing', 'loc': ('query', 'page_no'), 'msg': 'Input should be a valid integer, unable to parse string as an integer', 'input': 'undefined', 'url': 'https://errors.pydantic.dev/2.5/v/int_parsing'}]
[2024-07-23 08:06:41,443] [ERROR] app - Request invalid. [{'type': 'int_parsing', 'loc': ('query', 'page_no'), 'msg': 'Input should be a valid integer, unable to parse string as an integer', 'input': 'NaN', 'url': 'https://errors.pydantic.dev/2.5/v/int_parsing'}]
[2024-07-23 08:06:41,603] [ERROR] app - Request invalid. [{'type': 'int_parsing', 'loc': ('query', 'page_no'), 'msg': 'Input should be a valid integer, unable to parse string as an integer', 'input': 'undefined', 'url': 'https://errors.pydantic.dev/2.5/v/int_parsing'}]
[2024-07-23 08:10:47,288] [ERROR] app - Request invalid. [{'type': 'int_parsing', 'loc': ('query', 'per_page'), 'msg': 'Input should be a valid integer, unable to parse string as an integer', 'input': 'undefined', 'url': 'https://errors.pydantic.dev/2.5/v/int_parsing'}, {'type': 'int_parsing', 'loc': ('query', 'page_no'), 'msg': 'Input should be a valid integer, unable to parse string as an integer', 'input': 'undefined', 'url': 'https://errors.pydantic.dev/2.5/v/int_parsing'}]
[2024-07-23 08:10:47,391] [ERROR] app - Request invalid. [{'type': 'int_parsing', 'loc': ('query', 'per_page'), 'msg': 'Input should be a valid integer, unable to parse string as an integer', 'input': 'undefined', 'url': 'https://errors.pydantic.dev/2.5/v/int_parsing'}]
[2024-07-23 08:10:47,452] [ERROR] app - Request invalid. [{'type': 'int_parsing', 'loc': ('query', 'per_page'), 'msg': 'Input should be a valid integer, unable to parse string as an integer', 'input': 'undefined', 'url': 'https://errors.pydantic.dev/2.5/v/int_parsing'}, {'type': 'int_parsing', 'loc': ('query', 'page_no'), 'msg': 'Input should be a valid integer, unable to parse string as an integer', 'input': 'NaN', 'url': 'https://errors.pydantic.dev/2.5/v/int_parsing'}]
[2024-07-23 08:10:47,765] [ERROR] app - Request invalid. [{'type': 'int_parsing', 'loc': ('query', 'per_page'), 'msg': 'Input should be a valid integer, unable to parse string as an integer', 'input': 'undefined', 'url': 'https://errors.pydantic.dev/2.5/v/int_parsing'}, {'type': 'int_parsing', 'loc': ('query', 'page_no'), 'msg': 'Input should be a valid integer, unable to parse string as an integer', 'input': 'undefined', 'url': 'https://errors.pydantic.dev/2.5/v/int_parsing'}]
[2024-07-23 08:10:47,835] [ERROR] app - Request invalid. [{'type': 'int_parsing', 'loc': ('query', 'per_page'), 'msg': 'Input should be a valid integer, unable to parse string as an integer', 'input': 'undefined', 'url': 'https://errors.pydantic.dev/2.5/v/int_parsing'}]
[2024-07-23 08:14:18,928] [ERROR] app - Request invalid. [{'type': 'int_parsing', 'loc': ('query', 'per_page'), 'msg': 'Input should be a valid integer, unable to parse string as an integer', 'input': 'undefined', 'url': 'https://errors.pydantic.dev/2.5/v/int_parsing'}, {'type': 'int_parsing', 'loc': ('query', 'page_no'), 'msg': 'Input should be a valid integer, unable to parse string as an integer', 'input': 'undefined', 'url': 'https://errors.pydantic.dev/2.5/v/int_parsing'}]
[2024-07-23 08:14:18,952] [ERROR] app - Request invalid. [{'type': 'int_parsing', 'loc': ('query', 'per_page'), 'msg': 'Input should be a valid integer, unable to parse string as an integer', 'input': 'undefined', 'url': 'https://errors.pydantic.dev/2.5/v/int_parsing'}, {'type': 'int_parsing', 'loc': ('query', 'page_no'), 'msg': 'Input should be a valid integer, unable to parse string as an integer', 'input': 'NaN', 'url': 'https://errors.pydantic.dev/2.5/v/int_parsing'}]
[2024-07-23 08:14:37,032] [ERROR] app - Request invalid. [{'type': 'int_parsing', 'loc': ('query', 'per_page'), 'msg': 'Input should be a valid integer, unable to parse string as an integer', 'input': 'undefined', 'url': 'https://errors.pydantic.dev/2.5/v/int_parsing'}, {'type': 'int_parsing', 'loc': ('query', 'page_no'), 'msg': 'Input should be a valid integer, unable to parse string as an integer', 'input': 'undefined', 'url': 'https://errors.pydantic.dev/2.5/v/int_parsing'}]
[2024-07-23 08:14:37,093] [ERROR] app - Request invalid. [{'type': 'int_parsing', 'loc': ('query', 'per_page'), 'msg': 'Input should be a valid integer, unable to parse string as an integer', 'input': 'undefined', 'url': 'https://errors.pydantic.dev/2.5/v/int_parsing'}, {'type': 'int_parsing', 'loc': ('query', 'page_no'), 'msg': 'Input should be a valid integer, unable to parse string as an integer', 'input': 'NaN', 'url': 'https://errors.pydantic.dev/2.5/v/int_parsing'}]
[2024-07-23 08:15:02,799] [ERROR] app - Request invalid. [{'type': 'int_parsing', 'loc': ('query', 'per_page'), 'msg': 'Input should be a valid integer, unable to parse string as an integer', 'input': 'undefined', 'url': 'https://errors.pydantic.dev/2.5/v/int_parsing'}, {'type': 'int_parsing', 'loc': ('query', 'page_no'), 'msg': 'Input should be a valid integer, unable to parse string as an integer', 'input': 'undefined', 'url': 'https://errors.pydantic.dev/2.5/v/int_parsing'}]
[2024-07-23 08:15:02,896] [ERROR] app - Request invalid. [{'type': 'int_parsing', 'loc': ('query', 'per_page'), 'msg': 'Input should be a valid integer, unable to parse string as an integer', 'input': 'undefined', 'url': 'https://errors.pydantic.dev/2.5/v/int_parsing'}]
[2024-07-23 08:15:02,905] [ERROR] app - Request invalid. [{'type': 'int_parsing', 'loc': ('query', 'per_page'), 'msg': 'Input should be a valid integer, unable to parse string as an integer', 'input': 'undefined', 'url': 'https://errors.pydantic.dev/2.5/v/int_parsing'}, {'type': 'int_parsing', 'loc': ('query', 'page_no'), 'msg': 'Input should be a valid integer, unable to parse string as an integer', 'input': 'undefined', 'url': 'https://errors.pydantic.dev/2.5/v/int_parsing'}]
[2024-07-23 08:15:02,955] [ERROR] app - Request invalid. [{'type': 'int_parsing', 'loc': ('query', 'per_page'), 'msg': 'Input should be a valid integer, unable to parse string as an integer', 'input': 'undefined', 'url': 'https://errors.pydantic.dev/2.5/v/int_parsing'}]
[2024-07-23 08:15:03,023] [ERROR] app - Request invalid. [{'type': 'int_parsing', 'loc': ('query', 'per_page'), 'msg': 'Input should be a valid integer, unable to parse string as an integer', 'input': 'undefined', 'url': 'https://errors.pydantic.dev/2.5/v/int_parsing'}, {'type': 'int_parsing', 'loc': ('query', 'page_no'), 'msg': 'Input should be a valid integer, unable to parse string as an integer', 'input': 'NaN', 'url': 'https://errors.pydantic.dev/2.5/v/int_parsing'}]
[2024-07-23 08:17:20,966] [ERROR] app - Request invalid. [{'type': 'int_parsing', 'loc': ('query', 'page_no'), 'msg': 'Input should be a valid integer, unable to parse string as an integer', 'input': 'undefined', 'url': 'https://errors.pydantic.dev/2.5/v/int_parsing'}]
[2024-07-23 08:17:20,976] [ERROR] app - Request invalid. [{'type': 'int_parsing', 'loc': ('query', 'per_page'), 'msg': 'Input should be a valid integer, unable to parse string as an integer', 'input': 'undefined', 'url': 'https://errors.pydantic.dev/2.5/v/int_parsing'}]
[2024-07-23 08:17:20,978] [ERROR] app - Request invalid. [{'type': 'int_parsing', 'loc': ('query', 'per_page'), 'msg': 'Input should be a valid integer, unable to parse string as an integer', 'input': 'undefined', 'url': 'https://errors.pydantic.dev/2.5/v/int_parsing'}, {'type': 'int_parsing', 'loc': ('query', 'page_no'), 'msg': 'Input should be a valid integer, unable to parse string as an integer', 'input': 'NaN', 'url': 'https://errors.pydantic.dev/2.5/v/int_parsing'}]
[2024-07-23 08:17:21,007] [ERROR] app - Request invalid. [{'type': 'int_parsing', 'loc': ('query', 'per_page'), 'msg': 'Input should be a valid integer, unable to parse string as an integer', 'input': 'undefined', 'url': 'https://errors.pydantic.dev/2.5/v/int_parsing'}]
[2024-07-23 08:17:21,007] [ERROR] app - Request invalid. [{'type': 'int_parsing', 'loc': ('query', 'page_no'), 'msg': 'Input should be a valid integer, unable to parse string as an integer', 'input': 'undefined', 'url': 'https://errors.pydantic.dev/2.5/v/int_parsing'}]
[2024-07-23 08:17:30,922] [ERROR] app - Request invalid. [{'type': 'int_parsing', 'loc': ('query', 'page_no'), 'msg': 'Input should be a valid integer, unable to parse string as an integer', 'input': 'undefined', 'url': 'https://errors.pydantic.dev/2.5/v/int_parsing'}]
[2024-07-23 08:17:30,943] [ERROR] app - Request invalid. [{'type': 'int_parsing', 'loc': ('query', 'per_page'), 'msg': 'Input should be a valid integer, unable to parse string as an integer', 'input': 'undefined', 'url': 'https://errors.pydantic.dev/2.5/v/int_parsing'}]
[2024-07-23 08:17:30,966] [ERROR] app - Request invalid. [{'type': 'int_parsing', 'loc': ('query', 'page_no'), 'msg': 'Input should be a valid integer, unable to parse string as an integer', 'input': 'undefined', 'url': 'https://errors.pydantic.dev/2.5/v/int_parsing'}]
[2024-07-23 08:17:30,984] [ERROR] app - Request invalid. [{'type': 'int_parsing', 'loc': ('query', 'per_page'), 'msg': 'Input should be a valid integer, unable to parse string as an integer', 'input': 'undefined', 'url': 'https://errors.pydantic.dev/2.5/v/int_parsing'}]
[2024-07-23 08:17:31,191] [ERROR] app - Request invalid. [{'type': 'int_parsing', 'loc': ('query', 'per_page'), 'msg': 'Input should be a valid integer, unable to parse string as an integer', 'input': 'undefined', 'url': 'https://errors.pydantic.dev/2.5/v/int_parsing'}, {'type': 'int_parsing', 'loc': ('query', 'page_no'), 'msg': 'Input should be a valid integer, unable to parse string as an integer', 'input': 'NaN', 'url': 'https://errors.pydantic.dev/2.5/v/int_parsing'}]
[2024-07-23 08:19:01,452] [ERROR] app - Request invalid. [{'type': 'int_parsing', 'loc': ('query', 'per_page'), 'msg': 'Input should be a valid integer, unable to parse string as an integer', 'input': 'undefined', 'url': 'https://errors.pydantic.dev/2.5/v/int_parsing'}, {'type': 'int_parsing', 'loc': ('query', 'page_no'), 'msg': 'Input should be a valid integer, unable to parse string as an integer', 'input': 'NaN', 'url': 'https://errors.pydantic.dev/2.5/v/int_parsing'}]
[2024-07-23 08:19:29,087] [ERROR] app - Request invalid. [{'type': 'int_parsing', 'loc': ('query', 'per_page'), 'msg': 'Input should be a valid integer, unable to parse string as an integer', 'input': 'undefined', 'url': 'https://errors.pydantic.dev/2.5/v/int_parsing'}]
[2024-07-23 08:19:29,228] [ERROR] app - Request invalid. [{'type': 'int_parsing', 'loc': ('query', 'per_page'), 'msg': 'Input should be a valid integer, unable to parse string as an integer', 'input': 'undefined', 'url': 'https://errors.pydantic.dev/2.5/v/int_parsing'}]
[2024-07-23 08:19:29,257] [ERROR] app - Request invalid. [{'type': 'int_parsing', 'loc': ('query', 'per_page'), 'msg': 'Input should be a valid integer, unable to parse string as an integer', 'input': 'undefined', 'url': 'https://errors.pydantic.dev/2.5/v/int_parsing'}, {'type': 'int_parsing', 'loc': ('query', 'page_no'), 'msg': 'Input should be a valid integer, unable to parse string as an integer', 'input': 'NaN', 'url': 'https://errors.pydantic.dev/2.5/v/int_parsing'}]
[2024-07-23 08:21:57,558] [ERROR] app - Request invalid. [{'type': 'int_parsing', 'loc': ('query', 'per_page'), 'msg': 'Input should be a valid integer, unable to parse string as an integer', 'input': 'undefined', 'url': 'https://errors.pydantic.dev/2.5/v/int_parsing'}, {'type': 'int_parsing', 'loc': ('query', 'page_no'), 'msg': 'Input should be a valid integer, unable to parse string as an integer', 'input': 'NaN', 'url': 'https://errors.pydantic.dev/2.5/v/int_parsing'}]
[2024-07-23 19:38:13,653] [ERROR] app - Request invalid. [{'type': 'int_parsing', 'loc': ('query', 'page_no'), 'msg': 'Input should be a valid integer, unable to parse string as an integer', 'input': 'undefined', 'url': 'https://errors.pydantic.dev/2.5/v/int_parsing'}]
[2024-07-23 19:38:15,324] [ERROR] app - Request invalid. [{'type': 'int_parsing', 'loc': ('query', 'page_no'), 'msg': 'Input should be a valid integer, unable to parse string as an integer', 'input': 'undefined', 'url': 'https://errors.pydantic.dev/2.5/v/int_parsing'}]
